<?xml version="1.0"?>
<robot name="scout_mini">

    <!-- Vehicle Geometries -->
    <link name="base_link">
        <visual>
            <origin xyz="0 0 0" rpy="1.5707 0 -1.5707" />
            <geometry>
                <mesh filename="package://scout_description/meshes/scout_mini_base_link.dae" />
            </geometry>
        </visual>
        <collision>
            <origin xyz="0 0 0" rpy="1.5707 0 -1.5707" />
            <geometry>
                <mesh filename="package://scout_description/meshes/scout_mini_base_link.dae" />
            </geometry>
        </collision>
    </link>

    <link name="inertial_link">
        <inertial>
            <mass value="60" />
            <origin xyz="0.0 0.0 0.0" />
            <inertia ixx="2.288641" ixy="0" ixz="0" iyy="5.103976" iyz="0" izz="3.431465" />
        </inertial>
    </link>

    <joint name="inertial_joint" type="fixed">
        <origin xyz="0 0 0" rpy="0 0 0" />
        <parent link="base_link" />
        <child link="inertial_link" />
    </joint>

    <!-- Wheels -->
    <link name="front_right_wheel_link">
        <inertial>
            <mass value="3" />
            <origin xyz="0 0 0" />
            <inertia ixx="0.7171" ixy="0" ixz="0" iyy="0.7171" iyz="0" izz="0.1361" />
        </inertial>
        <visual>
            <origin xyz="0 0 0" rpy="0 0 0" />
            <geometry>
                <mesh filename="package://scout_description/meshes/wheel.dae" />
            </geometry>
        </visual>
        <collision>
            <origin xyz="0 0 0" rpy="0 0 0" />
            <geometry>
                <mesh filename="package://scout_description/meshes/wheel.dae" />
            </geometry>
        </collision>
    </link>
    <joint name="front_right_wheel" type="continuous">
        <origin xyz="0.2319755 -0.2082515 -0.100998" rpy="1.57 0 0" />
        <parent link="base_link" />
        <child link="front_right_wheel_link" />
        <axis xyz="0 0 -1" rpy="0 0 0" />
    </joint>

    <link name="front_left_wheel_link">
        <inertial>
            <mass value="3" />
            <origin xyz="0 0 0" />
            <inertia ixx="0.7171" ixy="0" ixz="0" iyy="0.7171" iyz="0" izz="0.1361" />
        </inertial>
        <visual>
            <origin xyz="0 0 0" rpy="0 0 0" />
            <geometry>
                <mesh filename="package://scout_description/meshes/wheel.dae" />
            </geometry>
        </visual>
        <collision>
            <origin xyz="0 0 0" rpy="0 0 0" />
            <geometry>
                <mesh filename="package://scout_description/meshes/wheel.dae" />
            </geometry>
        </collision>
    </link>
    <joint name="front_left_wheel" type="continuous">
        <origin xyz="0.2319755 0.2082515 -0.100998" rpy="-1.57 0 0" />
        <parent link="base_link" />
        <child link="front_left_wheel_link" />
        <axis xyz="0 0 -1" rpy="0 0 0" />
    </joint>

    <!-- Rear Wheels -->
    <link name="rear_left_wheel_link">
        <inertial>
            <mass value="3" />
            <origin xyz="0 0 0" />
            <inertia ixx="0.7171" ixy="0" ixz="0" iyy="0.7171" iyz="0" izz="0.1361" />
        </inertial>
        <visual>
            <origin xyz="0 0 0" rpy="0 0 0" />
            <geometry>
                <mesh filename="package://scout_description/meshes/wheel.dae" />
            </geometry>
        </visual>
        <collision>
            <origin xyz="0 0 0" rpy="0 0 0" />
            <geometry>
                <mesh filename="package://scout_description/meshes/wheel.dae" />
            </geometry>
        </collision>
    </link>
    <joint name="rear_left_wheel" type="continuous">
        <origin xyz="-0.2319755 0.2082515 -0.100998" rpy="-1.57 0 0" />
        <parent link="base_link" />
        <child link="rear_left_wheel_link" />
        <axis xyz="0 0 -1" rpy="0 0 0" />
    </joint>

    <link name="rear_right_wheel_link">
        <inertial>
            <mass value="3" />
            <origin xyz="0 0 0" />
            <inertia ixx="0.7171" ixy="0" ixz="0" iyy="0.7171" iyz="0" izz="0.1361" />
        </inertial>
        <visual>
            <origin xyz="0 0 0" rpy="0 0 0" />
            <geometry>
                <mesh filename="package://scout_description/meshes/wheel.dae" />
            </geometry>
        </visual>
        <collision>
            <origin xyz="0 0 0" rpy="0 0 0" />
            <geometry>
                <mesh filename="package://scout_description/meshes/wheel.dae" />
            </geometry>
        </collision>
    </link>
    <joint name="rear_right_wheel" type="continuous">
        <origin xyz="-0.2319755 -0.2082515 -0.100998" rpy="1.57 0 0" />
        <parent link="base_link" />
        <child link="rear_right_wheel_link" />
        <axis xyz="0 0 -1" rpy="0 0 0" />
    </joint>

    <!-- Mounts -->
    <link name="front_mount" />
    <joint name="front_mount_joint" type="fixed">
        <origin xyz="0.175 0 0.068999" rpy="0 0 0" />
        <parent link="base_link" />
        <child link="front_mount" />
    </joint>

    <link name="rear_mount" />
    <joint name="rear_mount_joint" type="fixed">
        <origin xyz="-0.175 0 0.068999" rpy="0 0 0" />
        <parent link="base_link" />
        <child link="rear_mount" />
    </joint>
</robot>